ERROR Internal Server Error: /aplicatie_ex/login
Traceback (most recent call last):
  File "C:\Users\nichi\AppData\Roaming\Python\Python312\site-packages\django\core\handlers\exception.py", line 55, in inner
    response = get_response(request)
               ^^^^^^^^^^^^^^^^^^^^^
  File "C:\Users\nichi\AppData\Roaming\Python\Python312\site-packages\django\core\handlers\base.py", line 197, in _get_response
    response = wrapped_callback(request, *callback_args, **callback_kwargs)
               ^^^^^^^^^^^^^^^^^^^^^^^^^^^^^^^^^^^^^^^^^^^^^^^^^^^^^^^^^^^^
  File "C:\Users\nichi\OneDrive\Desktop\uni\django\cafenea\aplicatie_ex\views.py", line 564, in custom_login_view
    login(request, user)
TypeError: login() takes 1 positional argument but 2 were given
ERROR "POST /aplicatie_ex/login HTTP/1.1" 500 68395
ERROR Internal Server Error: /aplicatie_ex/login
Traceback (most recent call last):
  File "C:\Users\nichi\AppData\Roaming\Python\Python312\site-packages\django\core\handlers\exception.py", line 55, in inner
    response = get_response(request)
               ^^^^^^^^^^^^^^^^^^^^^
  File "C:\Users\nichi\AppData\Roaming\Python\Python312\site-packages\django\core\handlers\base.py", line 197, in _get_response
    response = wrapped_callback(request, *callback_args, **callback_kwargs)
               ^^^^^^^^^^^^^^^^^^^^^^^^^^^^^^^^^^^^^^^^^^^^^^^^^^^^^^^^^^^^
  File "C:\Users\nichi\OneDrive\Desktop\uni\django\cafenea\aplicatie_ex\views.py", line 565, in custom_login_view
    login(request)
TypeError: login() missing 1 required positional argument: 'user'
ERROR "POST /aplicatie_ex/login HTTP/1.1" 500 68234
ERROR Internal Server Error: /aplicatie_ex/register
Traceback (most recent call last):
  File "C:\Users\nichi\AppData\Roaming\Python\Python312\site-packages\django\db\backends\utils.py", line 105, in _execute
    return self.cursor.execute(sql, params)
           ^^^^^^^^^^^^^^^^^^^^^^^^^^^^^^^^
psycopg2.errors.UniqueViolation: duplicate key value violates unique constraint "aplicatie_ex_customuser_username_key"
DETAIL:  Key (username)=(iulianichita18) already exists.


The above exception was the direct cause of the following exception:

Traceback (most recent call last):
  File "C:\Users\nichi\AppData\Roaming\Python\Python312\site-packages\django\core\handlers\exception.py", line 55, in inner
    response = get_response(request)
               ^^^^^^^^^^^^^^^^^^^^^
  File "C:\Users\nichi\AppData\Roaming\Python\Python312\site-packages\django\core\handlers\base.py", line 197, in _get_response
    response = wrapped_callback(request, *callback_args, **callback_kwargs)
               ^^^^^^^^^^^^^^^^^^^^^^^^^^^^^^^^^^^^^^^^^^^^^^^^^^^^^^^^^^^^
  File "C:\Users\nichi\OneDrive\Desktop\uni\django\cafenea\aplicatie_ex\views.py", line 553, in register_view
    form.save()
  File "C:\Users\nichi\OneDrive\Desktop\uni\django\cafenea\aplicatie_ex\forms.py", line 338, in save
    user.save()
  File "C:\Users\nichi\AppData\Roaming\Python\Python312\site-packages\django\contrib\auth\base_user.py", line 62, in save
    super().save(*args, **kwargs)
  File "C:\Users\nichi\AppData\Roaming\Python\Python312\site-packages\django\db\models\base.py", line 891, in save
    self.save_base(
  File "C:\Users\nichi\AppData\Roaming\Python\Python312\site-packages\django\db\models\base.py", line 997, in save_base
    updated = self._save_table(
              ^^^^^^^^^^^^^^^^^
  File "C:\Users\nichi\AppData\Roaming\Python\Python312\site-packages\django\db\models\base.py", line 1160, in _save_table
    results = self._do_insert(
              ^^^^^^^^^^^^^^^^
  File "C:\Users\nichi\AppData\Roaming\Python\Python312\site-packages\django\db\models\base.py", line 1201, in _do_insert
    return manager._insert(
           ^^^^^^^^^^^^^^^^
  File "C:\Users\nichi\AppData\Roaming\Python\Python312\site-packages\django\db\models\manager.py", line 87, in manager_method
    return getattr(self.get_queryset(), name)(*args, **kwargs)
           ^^^^^^^^^^^^^^^^^^^^^^^^^^^^^^^^^^^^^^^^^^^^^^^^^^^
  File "C:\Users\nichi\AppData\Roaming\Python\Python312\site-packages\django\db\models\query.py", line 1847, in _insert
    return query.get_compiler(using=using).execute_sql(returning_fields)
           ^^^^^^^^^^^^^^^^^^^^^^^^^^^^^^^^^^^^^^^^^^^^^^^^^^^^^^^^^^^^^
  File "C:\Users\nichi\AppData\Roaming\Python\Python312\site-packages\django\db\models\sql\compiler.py", line 1836, in execute_sql
    cursor.execute(sql, params)
  File "C:\Users\nichi\AppData\Roaming\Python\Python312\site-packages\django\db\backends\utils.py", line 122, in execute
    return super().execute(sql, params)
           ^^^^^^^^^^^^^^^^^^^^^^^^^^^^
  File "C:\Users\nichi\AppData\Roaming\Python\Python312\site-packages\django\db\backends\utils.py", line 79, in execute
    return self._execute_with_wrappers(
           ^^^^^^^^^^^^^^^^^^^^^^^^^^^^
  File "C:\Users\nichi\AppData\Roaming\Python\Python312\site-packages\django\db\backends\utils.py", line 92, in _execute_with_wrappers
    return executor(sql, params, many, context)
           ^^^^^^^^^^^^^^^^^^^^^^^^^^^^^^^^^^^^
  File "C:\Users\nichi\AppData\Roaming\Python\Python312\site-packages\django\db\backends\utils.py", line 100, in _execute
    with self.db.wrap_database_errors:
  File "C:\Users\nichi\AppData\Roaming\Python\Python312\site-packages\django\db\utils.py", line 91, in __exit__
    raise dj_exc_value.with_traceback(traceback) from exc_value
  File "C:\Users\nichi\AppData\Roaming\Python\Python312\site-packages\django\db\backends\utils.py", line 105, in _execute
    return self.cursor.execute(sql, params)
           ^^^^^^^^^^^^^^^^^^^^^^^^^^^^^^^^
django.db.utils.IntegrityError: duplicate key value violates unique constraint "aplicatie_ex_customuser_username_key"
DETAIL:  Key (username)=(iulianichita18) already exists.

ERROR "POST /aplicatie_ex/register HTTP/1.1" 500 159636
